<robot name="kartezjan">
	<link name="base_link">
		<visual>
		<origin xyz="0 0 1" rpy="0 0 0" />
			<geometry>
				<cylinder length="2" radius="0.1"/>
			</geometry>
		</visual>
	</link>

	<link name="link1">
		<visual>
		<origin xyz="0 0 1" rpy="0 0 0" />
			<geometry>
				<cylinder length="2" radius="0.1"/>
			</geometry>
		</visual>
	</link>

	<link name="link2">
		<visual>
		<origin xyz="0 0 1" rpy="0 0 0" />
			<geometry>
				<cylinder length="2" radius="0.1"/>
			</geometry>
		</visual>
	</link>

	<link name="link3">
		<visual>
			<geometry>
				<box size="0.5 0.5 0.5"/>
			</geometry>
		</visual>
	</link>

	<joint name="joint1" type="prismatic">
		<parent link="base_link"/>
		<child link="link1"/>
		<origin xyz="0 0 2" rpy="1.5708 1.5708 0 " />
		<limit effort="30" velocity="1.0" lower="0" upper="2" />
	</joint>

	<joint name="joint2" type="prismatic">
		<parent link="link1"/>
		<child link="link2"/>
		<origin xyz="0 0 2" rpy="1.5708 1.5708 0 " />
		<limit effort="30" velocity="1.0" lower="0" upper="2" />
	</joint>

	<joint name="joint3" type="prismatic">
		<parent link="link2"/>
		<child link="link3"/>
		<origin xyz="0 0 2" rpy="0 0 0" />
		<limit effort="30" velocity="1.0" lower="0" upper="2" />
	</joint>
</robot>
